Workbook

Sheet Resumo
A1: Prophet × GARCH+SVM/XGBoost — 10 principais ações
A2: GARCH(1,1) próprio por papel; SVM/XGBoost/HAR ajustados uma vez (treino+validação); Prophet reajustado a cada 21 pregões em janela expansiva, nunca prevendo mais que isso à frente sem se reancorar; split cronológico 60/15/25
A4: Limiar de Bonferroni — família Direção (80 testes): | E4: =0.05/80 -> 0.000625
A6: Ticker | B6: Direção: melhor clássico | C6: Acerto clássico | D6: Direção: Prophet | E6: Prophet ganha? | F6: Volatilidade: Prophet vs régua justa (R²-OS) | G6: Preço: Prophet vs régua justa (R²-OS) | H6: Leitura
A7: VALE3 | B7: SVM (preço) | C7: 0.5078 | D7: 0.5026 | E7: Não | F7: -0.9556 | G7: -6.0948 | H7: pior que não fazer nada, nos dois alvos contínuos
A8: ITUB4 | B8: XGBoost (preço) | C8: 0.487 | D8: 0.4991 | E8: Sim | F8: -2.5586 | G8: -2.2261 | H8: pior que não fazer nada, nos dois alvos contínuos
A9: PETR4 | B9: SVM (preço) | C9: 0.5181 | D9: 0.4767 | E9: Não | F9: -1.6029 | G9: -5.3278 | H9: pior que não fazer nada, nos dois alvos contínuos
A10: SBSP3 | B10: SVM (preço) | C10: 0.4957 | D10: 0.5026 | E10: Sim | F10: -1.5554 | G10: -2.0864 | H10: pior que não fazer nada, nos dois alvos contínuos
A11: BBDC4 | B11: XGBoost (preço) | C11: 0.5095 | D11: 0.4629 | E11: Não | F11: -0.4746 | G11: -5.1527 | H11: pior que não fazer nada, nos dois alvos contínuos
A12: B3SA3 | B12: XGBoost (preço) | C12: 0.5233 | D12: 0.4888 | E12: Não | F12: -0.8872 | G12: -3.8086 | H12: pior que não fazer nada, nos dois alvos contínuos
A13: ITSA4 | B13: SVM (preço) | C13: 0.5164 | D13: 0.5112 | E13: Não | F13: -2.5453 | G13: -3.3046 | H13: pior que não fazer nada, nos dois alvos contínuos
A14: BPAC11 | B14: XGBoost (preço) | C14: 0.5216 | D14: 0.4646 | E14: Não | F14: -0.7374 | G14: -4.8427 | H14: pior que não fazer nada, nos dois alvos contínuos
A15: BBAS3 | B15: SVM (preço) | C15: 0.506 | D15: 0.5095 | E15: Sim | F15: -0.7649 | G15: -3.0608 | H15: pior que não fazer nada, nos dois alvos contínuos
A16: ABEV3 | B16: XGBoost (preço) | C16: 0.532 | D16: 0.5009 | E16: Não | F16: -0.4868 | G16: -1.7958 | H16: pior que não fazer nada, nos dois alvos contínuos
A18: Conclusão: a régua destas duas colunas é a comparação JUSTA — a 'ingênua ancorada', que recebe exatamente a mesma informação que o Prophet (o último valor conhecido antes do bloco de 21 pregões) e simplesmente a segura. Em 10 de 10 papéis o Prophet ficou PIOR que essa régua na volatilidade, e em 10 de 10 no preço — ou seja, extrapolar a tendência atrapalhou em vez de ajudar. Na direção, o Prophet perdeu do melhor modelo clássico em 7 de 10 papéis. Ver a aba 'Notas e metodologia' para por que esta régua, e não a ingênua diária, é a comparação correta.

Sheet Direção
A1: Ticker | B1: Braço | C1: Classe majoritária | D1: Acurácia | E1: AUC | F1: % dias em que prevê ALTA | G1: p vs majoritária | H1: Passa (p<0,05)? | I1: Sobrevive Bonferroni?
A2: VALE3 | B2: SVM (preço) | C2: 0.506 | D2: 0.5078 | E2: 0.5037 | F2: 0.788 | G2: 0.96685294 | H2: =IF(G2<0.05,"Sim","Não") -> Não | I2: =IF(G2<Resumo!$E$4,"Sim","Não") -> Não
A3: VALE3 | B3: XGBoost (preço) | C3: 0.506 | D3: 0.4646 | E3: 0.4766 | F3: 0.496 | G3: 0.050678822 | H3: =IF(G3<0.05,"Sim","Não") -> Não | I3: =IF(G3<Resumo!$E$4,"Sim","Não") -> Não
A4: VALE3 | B4: SVM (preço+CVM) | C4: 0.506 | D4: 0.4888 | E4: 0.511 | F4: 0.751 | G4: 0.40626098 | H4: =IF(G4<0.05,"Sim","Não") -> Não | I4: =IF(G4<Resumo!$E$4,"Sim","Não") -> Não
A5: VALE3 | B5: XGBoost (preço+CVM) | C5: 0.506 | D5: 0.4905 | E5: 0.4783 | F5: 0.525 | G5: 0.45480471 | H5: =IF(G5<0.05,"Sim","Não") -> Não | I5: =IF(G5<Resumo!$E$4,"Sim","Não") -> Não
A6: VALE3 | B6: Prophet (preço) | C6: 0.506 | D6: 0.5026 | E6: — | F6: 0.261 | G6: 0.86809144 | H6: =IF(G6<0.05,"Sim","Não") -> Não | I6: =IF(G6<Resumo!$E$4,"Sim","Não") -> Não
A7: VALE3 | B7: Prophet (preço+CVM) | C7: 0.506 | D7: 0.5026 | E7: — | F7: 0.261 | G7: 0.86809144 | H7: =IF(G7<0.05,"Sim","Não") -> Não | I7: =IF(G7<Resumo!$E$4,"Sim","Não") -> Não
A8: ITUB4 | B8: SVM (preço) | C8: 0.5337 | D8: 0.4819 | E8: 0.4992 | F8: 0.523 | G8: 0.013919683 | H8: =IF(G8<0.05,"Sim","Não") -> Sim | I8: =IF(G8<Resumo!$E$4,"Sim","Não") -> Não
A9: ITUB4 | B9: XGBoost (preço) | C9: 0.5337 | D9: 0.487 | E9: 0.4679 | F9: 0.511 | G9: 0.027184398 | H9: =IF(G9<0.05,"Sim","Não") -> Sim | I9: =IF(G9<Resumo!$E$4,"Sim","Não") -> Não
A10: ITUB4 | B10: SVM (preço+CVM) | C10: 0.5337 | D10: 0.4767 | E10: 0.5102 | F10: 0.566 | G10: 0.0067297847 | H10: =IF(G10<0.05,"Sim","Não") -> Sim | I10: =IF(G10<Resumo!$E$4,"Sim","Não") -> Não
A11: ITUB4 | B11: XGBoost (preço+CVM) | C11: 0.5337 | D11: 0.5043 | E11: 0.496 | F11: 0.473 | G11: 0.15699695 | H11: =IF(G11<0.05,"Sim","Não") -> Não | I11: =IF(G11<Resumo!$E$4,"Sim","Não") -> Não
A12: ITUB4 | B12: Prophet (preço) | C12: 0.5337 | D12: 0.4991 | E12: — | F12: 0.423 | G12: 0.095887083 | H12: =IF(G12<0.05,"Sim","Não") -> Não | I12: =IF(G12<Resumo!$E$4,"Sim","Não") -> Não
A13: ITUB4 | B13: Prophet (preço+CVM) | C13: 0.5337 | D13: 0.4991 | E13: — | F13: 0.423 | G13: 0.095887083 | H13: =IF(G13<0.05,"Sim","Não") -> Não | I13: =IF(G13<Resumo!$E$4,"Sim","Não") -> Não
A14: PETR4 | B14: SVM (preço) | C14: 0.532 | D14: 0.5181 | E14: 0.504 | F14: 0.955 | G14: 0.50558274 | H14: =IF(G14<0.05,"Sim","Não") -> Não | I14: =IF(G14<Resumo!$E$4,"Sim","Não") -> Não
A15: PETR4 | B15: XGBoost (preço) | C15: 0.532 | D15: 0.5181 | E15: 0.5157 | F15: 0.523 | G15: 0.50558274 | H15: =IF(G15<0.05,"Sim","Não") -> Não | I15: =IF(G15<Resumo!$E$4,"Sim","Não") -> Não
A16: PETR4 | B16: SVM (preço+CVM) | C16: 0.532 | D16: 0.5216 | E16: 0.474 | F16: 0.959 | G16: 0.61757648 | H16: =IF(G16<0.05,"Sim","Não") -> Não | I16: =IF(G16<Resumo!$E$4,"Sim","Não") -> Não
A17: PETR4 | B17: XGBoost (preço+CVM) | C17: 0.532 | D17: 0.5164 | E17: 0.5285 | F17: 0.646 | G17: 0.45388279 | H17: =IF(G17<0.05,"Sim","Não") -> Não | I17: =IF(G17<Resumo!$E$4,"Sim","Não") -> Não
A18: PETR4 | B18: Prophet (preço) | C18: 0.532 | D18: 0.4767 | E18: — | F18: 0.672 | G18: 0.0086450372 | H18: =IF(G18<0.05,"Sim","Não") -> Sim | I18: =IF(G18<Resumo!$E$4,"Sim","Não") -> Não
A19: PETR4 | B19: Prophet (preço+CVM) | C19: 0.532 | D19: 0.4784 | E19: — | F19: 0.67 | G19: 0.01101359 | H19: =IF(G19<0.05,"Sim","Não") -> Sim | I19: =IF(G19<Resumo!$E$4,"Sim","Não") -> Não
A20: SBSP3 | B20: SVM (preço) | C20: 0.5078 | D20: 0.4957 | E20: 0.4967 | F20: 0.701 | G20: 0.56100674 | H20: =IF(G20<0.05,"Sim","Não") -> Não | I20: =IF(G20<Resumo!$E$4,"Sim","Não") -> Não
A21: SBSP3 | B21: XGBoost (preço) | C21: 0.5078 | D21: 0.456 | E21: 0.4635 | F21: 0.599 | G21: 0.01412658 | H21: =IF(G21<0.05,"Sim","Não") -> Sim | I21: =IF(G21<Resumo!$E$4,"Sim","Não") -> Não
A22: SBSP3 | B22: SVM (preço+CVM) | C22: 0.5078 | D22: 0.506 | E22: 0.4997 | F22: 0.715 | G22: 0.93381509 | H22: =IF(G22<0.05,"Sim","Não") -> Não | I22: =IF(G22<Resumo!$E$4,"Sim","Não") -> Não
A23: SBSP3 | B23: XGBoost (preço+CVM) | C23: 0.5078 | D23: 0.4525 | E23: 0.4566 | F23: 0.603 | G23: 0.0087743495 | H23: =IF(G23<0.05,"Sim","Não") -> Sim | I23: =IF(G23<Resumo!$E$4,"Sim","Não") -> Não
A24: SBSP3 | B24: Prophet (preço) | C24: 0.5078 | D24: 0.5026 | E24: — | F24: 0.449 | G24: 0.80325299 | H24: =IF(G24<0.05,"Sim","Não") -> Não | I24: =IF(G24<Resumo!$E$4,"Sim","Não") -> Não
A25: SBSP3 | B25: Prophet (preço+CVM) | C25: 0.5078 | D25: 0.5026 | E25: — | F25: 0.449 | G25: 0.80325299 | H25: =IF(G25<0.05,"Sim","Não") -> Não | I25: =IF(G25<Resumo!$E$4,"Sim","Não") -> Não
A26: BBDC4 | B26: SVM (preço) | C26: 0.5216 | D26: 0.4974 | E26: 0.5055 | F26: 0.285 | G26: 0.24449384 | H26: =IF(G26<0.05,"Sim","Não") -> Não | I26: =IF(G26<Resumo!$E$4,"Sim","Não") -> Não
A27: BBDC4 | B27: XGBoost (preço) | C27: 0.5216 | D27: 0.5095 | E27: 0.4963 | F27: 0.48 | G27: 0.56067242 | H27: =IF(G27<0.05,"Sim","Não") -> Não | I27: =IF(G27<Resumo!$E$4,"Sim","Não") -> Não
A28: BBDC4 | B28: SVM (preço+CVM) | C28: 0.5216 | D28: 0.4801 | E28: 0.4982 | F28: 0.043 | G28: 0.050479827 | H28: =IF(G28<0.05,"Sim","Não") -> Não | I28: =IF(G28<Resumo!$E$4,"Sim","Não") -> Não
A29: BBDC4 | B29: XGBoost (preço+CVM) | C29: 0.5216 | D29: 0.494 | E29: 0.5051 | F29: 0.475 | G29: 0.18346728 | H29: =IF(G29<0.05,"Sim","Não") -> Não | I29: =IF(G29<Resumo!$E$4,"Sim","Não") -> Não
A30: BBDC4 | B30: Prophet (preço) | C30: 0.5216 | D30: 0.4629 | E30: — | F30: 0.399 | G30: 0.0052749237 | H30: =IF(G30<0.05,"Sim","Não") -> Sim | I30: =IF(G30<Resumo!$E$4,"Sim","Não") -> Não
A31: BBDC4 | B31: Prophet (preço+CVM) | C31: 0.5216 | D31: 0.4594 | E31: — | F31: 0.396 | G31: 0.0031094622 | H31: =IF(G31<0.05,"Sim","Não") -> Sim | I31: =IF(G31<Resumo!$E$4,"Sim","Não") -> Não
A32: B3SA3 | B32: SVM (preço) | C32: 0.506 | D32: 0.4922 | E32: 0.4622 | F32: 0.185 | G32: 0.50645316 | H32: =IF(G32<0.05,"Sim","Não") -> Não | I32: =IF(G32<Resumo!$E$4,"Sim","Não") -> Não
A33: B3SA3 | B33: XGBoost (preço) | C33: 0.506 | D33: 0.5233 | E33: 0.5277 | F33: 0.423 | G33: 0.42974522 | H33: =IF(G33<0.05,"Sim","Não") -> Não | I33: =IF(G33<Resumo!$E$4,"Sim","Não") -> Não
A34: B3SA3 | B34: SVM (preço+CVM) | C34: 0.506 | D34: 0.5026 | E34: 0.4769 | F34: 0.261 | G34: 0.86809144 | H34: =IF(G34<0.05,"Sim","Não") -> Não | I34: =IF(G34<Resumo!$E$4,"Sim","Não") -> Não
A35: B3SA3 | B35: XGBoost (preço+CVM) | C35: 0.506 | D35: 0.5285 | E35: 0.5208 | F35: 0.39 | G35: 0.2987805 | H35: =IF(G35<0.05,"Sim","Não") -> Não | I35: =IF(G35<Resumo!$E$4,"Sim","Não") -> Não
A36: B3SA3 | B36: Prophet (preço) | C36: 0.506 | D36: 0.4888 | E36: — | F36: 0.378 | G36: 0.40626098 | H36: =IF(G36<0.05,"Sim","Não") -> Não | I36: =IF(G36<Resumo!$E$4,"Sim","Não") -> Não
A37: B3SA3 | B37: Prophet (preço+CVM) | C37: 0.506 | D37: 0.4888 | E37: — | F37: 0.375 | G37: 0.40626098 | H37: =IF(G37<0.05,"Sim","Não") -> Não | I37: =IF(G37<Resumo!$E$4,"Sim","Não") -> Não
A38: ITSA4 | B38: SVM (preço) | C38: 0.5181 | D38: 0.5164 | E38: 0.5215 | F38: 0.339 | G38: 0.93377732 | H38: =IF(G38<0.05,"Sim","Não") -> Não | I38: =IF(G38<Resumo!$E$4,"Sim","Não") -> Não
A39: ITSA4 | B39: XGBoost (preço) | C39: 0.5181 | D39: 0.5043 | E39: 0.5009 | F39: 0.489 | G39: 0.50618963 | H39: =IF(G39<0.05,"Sim","Não") -> Não | I39: =IF(G39<Resumo!$E$4,"Sim","Não") -> Não
A40: ITSA4 | B40: SVM (preço+CVM) | C40: 0.5181 | D40: 0.506 | E40: 0.5413 | F40: 0.218 | G40: 0.56078412 | H40: =IF(G40<0.05,"Sim","Não") -> Não | I40: =IF(G40<Resumo!$E$4,"Sim","Não") -> Não
...

Sheet Volatilidade
A1: Ticker | B1: Braço | C1: MAE | D1: RMSE | E1: R²-OS vs HAR (info diária) | F1: R²-OS vs ancorada (COMPARAÇÃO JUSTA)
A2: VALE3 | B2: HAR (GARCH, referência) | C2: 0.0656 | D2: 0.0908 | E2: 0 | F2: 0.8888
A3: VALE3 | B3: HAR + CVM | C3: 0.0681 | D3: 0.0932 | E3: -0.0533 | F3: 0.8829
A4: VALE3 | B4: Ingênua ancorada (mesma info do Prophet) | C4: 0.1958 | D4: 0.2722 | E4: -7.9938 | F4: 0
A5: VALE3 | B5: Prophet (volatilidade) | C5: 0.3106 | D5: 0.3807 | E5: -16.5887 | F5: -0.9556
A6: VALE3 | B6: Prophet (volatilidade+CVM) | C6: 0.3104 | D6: 0.3819 | E6: -16.6997 | F6: -0.968
A7: ITUB4 | B7: HAR (GARCH, referência) | C7: 0.034 | D7: 0.048 | E7: 0 | F7: 0.8718
A8: ITUB4 | B8: HAR + CVM | C8: 0.0339 | D8: 0.048 | E8: 0.0006 | F8: 0.8719
A9: ITUB4 | B9: Ingênua ancorada (mesma info do Prophet) | C9: 0.1026 | D9: 0.1341 | E9: -6.8007 | F9: 0
A10: ITUB4 | B10: Prophet (volatilidade) | C10: 0.1932 | D10: 0.253 | E10: -26.7595 | F10: -2.5586
A11: ITUB4 | B11: Prophet (volatilidade+CVM) | C11: 0.1931 | D11: 0.2529 | E11: -26.7319 | F11: -2.5551
A12: PETR4 | B12: HAR (GARCH, referência) | C12: 0.0687 | D12: 0.0967 | E12: 0 | F12: 0.8776
A13: PETR4 | B13: HAR + CVM | C13: 0.0692 | D13: 0.0968 | E13: -0.0028 | F13: 0.8773
... A51: ABEV3 | B51: Prophet (volatilidade+CVM) | C51: 0.2212 | D51: 0.32 | E51: -19.3465 | F51: -0.4774

Sheet Preço
A1: Ticker | B1: Braço | C1: MAE (R$) | D1: RMSE (R$) | E1: R²-OS vs ingênua diária (info diária) | F1: R²-OS vs ancorada (COMPARAÇÃO JUSTA)
A2: VALE3 | B2: Ingênua diária (fechamento de ontem) | C2: 0.7048 | D2: 1.0097 | E2: 0 | F2: 0.9168
A3: VALE3 | B3: Ingênua ancorada (mesma info do Prophet) | C3: 2.5302 | D3: 3.4999 | E3: -11.0138 | F3: 0
A4: VALE3 | B4: Prophet (preço) | C4: 6.5907 | D4: 9.3223 | E4: -84.2355 | F4: -6.0948
A5: VALE3 | B5: Prophet (preço+CVM) | C5: 6.6105 | D5: 9.348 | E5: -84.7056 | F5: -6.1339
A6: ITUB4 | B6: Ingênua diária (fechamento de ontem) | C6: 0.3584 | D6: 0.4897 | E6: 0 | F6: 0.9293
A7: ITUB4 | B7: Ingênua ancorada (mesma info do Prophet) | C7: 1.3571 | D7: 1.8414 | E7: -13.1365 | F7: 0
A8: ITUB4 | B8: Prophet (preço) | C8: 2.6348 | D8: 3.3073 | E8: -44.6052 | F8: -2.2261
A9: ITUB4 | B9: Prophet (preço+CVM) | C9: 2.6419 | D9: 3.311 | E9: -44.7085 | F9: -2.2334
A10: PETR4 | B10: Ingênua diária (fechamento de ontem) | C10: 0.384 | D10: 0.5384 | E10: 0 | F10: 0.9332
A11: PETR4 | B11: Ingênua ancorada (mesma info do Prophet) | C11: 1.4181 | D11: 2.0836 | E11: -13.9759 | F11: 0
A12: PETR4 | B12: Prophet (preço) | C12: 3.9094 | D12: 5.2415 | E12: -93.7649 | F12: -5.3278
A13: PETR4 | B13: Prophet (preço+CVM) | C13: 3.9175 | D13: 5.2445 | E13: -93.8731 | F13: -5.3351
... A41: ABEV3 | B41: Prophet (preço+CVM) | C41: 1.0765 | D41: 1.3224 | E41: -45.1413 | F41: -1.8

Sheet McNemar
A1: Ticker | B1: Comparação | C1: Ganhou (novo) | D1: Perdeu (antigo) | E1: p-valor | F1: Significativo (p<0,05)?
A2: VALE3 | B2: Prophet(preço) supera o melhor entre SVM/XGB(preço)? | C2: 184 | D2: 187 | E2: 0.91731881 | F2: =IF(E2<0.05,"Sim","Não") -> Não
A3: VALE3 | B3: CVM ajuda o Prophet na direção? | C3: 2 | D3: 2 | E3: 1 | F3: =IF(E3<0.05,"Sim","Não") -> Não
A4: ITUB4 | B4: Prophet(preço) supera o melhor entre SVM/XGB(preço)? | C4: 148 | D4: 141 | E4: 0.72419972 | F4: =IF(E4<0.05,"Sim","Não") -> Não
A5: ITUB4 | B5: CVM ajuda o Prophet na direção? | C5: 0 | D5: 0 | E5: 1 | F5: =IF(E5<0.05,"Sim","Não") -> Não
A6: PETR4 | B6: Prophet(preço) supera o melhor entre SVM/XGB(preço)? | C6: 79 | D6: 103 | E6: 0.087940011 | F6: =IF(E6<0.05,"Sim","Não") -> Não
A7: PETR4 | B7: CVM ajuda o Prophet na direção? | C7: 1 | D7: 0 | E7: 1 | F7: =IF(E7<0.05,"Sim","Não") -> Não
A8: SBSP3 | B8: Prophet(preço) supera o melhor entre SVM/XGB(preço)? | C8: 143 | D8: 139 | E8: 0.85825492 | F8: =IF(E8<0.05,"Sim","Não") -> Não
A9: SBSP3 | B9: CVM ajuda o Prophet na direção? | C9: 1 | D9: 1 | E9: 1 | F9: =IF(E9<0.05,"Sim","Não") -> Não
A10: BBDC4 | B10: Prophet(preço) supera o melhor entre SVM/XGB(preço)? | C10: 116 | D10: 143 | E10: 0.10600805 | F10: =IF(E10<0.05,"Sim","Não") -> Não
A11: BBDC4 | B11: CVM ajuda o Prophet na direção? | C11: 0 | D11: 2 | E11: 0.5 | F11: =IF(E11<0.05,"Sim","Não") -> Não
A12: B3SA3 | B12: Prophet(preço) supera o melhor entre SVM/XGB(preço)? | C12: 117 | D12: 137 | E12: 0.23313219 | F12: =IF(E12<0.05,"Sim","Não") -> Não
A13: B3SA3 | B13: CVM ajuda o Prophet na direção? | C13: 1 | D13: 1 | E13: 1 | F13: =IF(E13<0.05,"Sim","Não") -> Não
... A21: ABEV3 | B21: CVM ajuda o Prophet na direção? | C21: 0 | D21: 0 | E21: 1 | F21: =IF(E21<0.05,"Sim","Não") -> Não

Sheet Notas e metodologia
A1: O que é o Prophet, e o que NÃO é
A2: Biblioteca de previsão de série temporal (Meta). NÃO classifica texto. O sentimento usado aqui vem do FinBERT, já classificado antes desta pesquisa nos comunicados da CVM — o Prophet só entra como mais um modelo de previsão.
A4: Por que o Prophet é reajustado a cada 21 pregões, e os outros não
A5: Um primeiro teste ajustou o Prophet uma vez só e pediu para prever os 579 pregões de teste inteiros de uma vez — quase 2 anos à frente sem nunca se reancorar. A tendência disparou: R²-OS de -8.325% na volatilidade e -69.604% no preço, um resultado degenerado. Aqui ele é reajustado a cada ~21 pregões (janela expansiva), nunca prevendo mais que um mês à frente de uma vez.
A7: A régua JUSTA — e por que ela existe nesta planilha
A8: A primeira versão desta comparação era DESLEAL com o Prophet, e isso foi corrigido: a ingênua diária enxerga o fechamento de ONTEM em todo dia do teste, enquanto o Prophet, no 21º dia de um bloco, ainda está olhando o que sabia 21 pregões atrás. Comparar os dois assim é comparar quem responde com a notícia de ontem contra quem responde com a do mês passado. Por isso existe a 'ingênua ancorada': ela recebe EXATAMENTE a mesma informação do Prophet (o último valor antes do bloco) e simplesmente segura esse valor. É contra ela que o Prophet deve ser julgado — e é a coluna marcada como COMPARAÇÃO JUSTA.
A10: O achado, agora que a comparação é justa
A11: Mesmo com a mesma informação, o Prophet fica PIOR que segurar o último valor conhecido — tanto na volatilidade quanto no preço, nos 10 papéis. Ou seja: extrapolar a tendência ATRAPALHA em vez de ajudar, nesta série. Não é um empate nem um ganho pequeno; é um resultado negativo claro. Faz sentido: preço de ação é quase um passeio aleatório, e a tendência que o Prophet projeta para a frente costuma ter virado antes de o bloco acabar (ex.: a PETR4 foi de ~R$35 a ~R$46 entre fev e abr/2026, em degraus diários de até 5% — conferido contra os dados brutos, não é erro de base).
A13: A ingênua DIÁRIA, e a pergunta de 12/10 sobre esforço computacional
A14: A coluna 'R²-OS vs ingênua diária' mostra o quanto se ganha só por se reatualizar todo dia em vez de uma vez por mês — e o ganho é enorme. Isso responde, com número desta pesquisa, à pergunta do professor na mentoria de 12/10: aqui, a frequência de reatualização vale MUITO mais que a sofisticação do modelo. Reajustar o Prophet todo dia custaria ~21x mais processamento (cada reajuste leva ~1,3s), e ainda assim ele partiria atrás de uma régua que é de graça.
A16: Direção — como o Prophet 'vota'
A17: O Prophet prevê o PREÇO; a direção prevista é o sinal da diferença entre o preço previsto e o fechamento de ontem. Por isso o Prophet não tem AUC nesta tabela — ele não produz probabilidade de classe, só um valor previsto.
... A23: 80 testes (10 papéis × (6 braços vs majoritária + 2 McNemar)). Limiar na aba Resumo, célula E4 — todas as colunas 'Sobrevive Bonferroni?' das abas Direção e McNemar referenciam essa mesma célula.
